#VRML_SIM R2023b utf8

EXTERNPROTO "https://raw.githubusercontent.com/cyberbotics/webots/R2023b/projects/objects/backgrounds/protos/TexturedBackground.proto"
EXTERNPROTO "https://raw.githubusercontent.com/cyberbotics/webots/R2023b/projects/objects/backgrounds/protos/TexturedBackgroundLight.proto"
EXTERNPROTO "https://raw.githubusercontent.com/cyberbotics/webots/R2023b/projects/objects/floors/protos/RectangleArena.proto"
EXTERNPROTO "https://raw.githubusercontent.com/cyberbotics/webots/R2023b/projects/appearances/protos/Parquetry.proto"
EXTERNPROTO "https://raw.githubusercontent.com/cyberbotics/webots/R2023b/projects/objects/apartment_structure/protos/Wall.proto"
EXTERNPROTO "https://raw.githubusercontent.com/cyberbotics/webots/R2023b/projects/objects/cabinet/protos/Cabinet.proto"

WorldInfo {
}
Viewpoint {
  orientation 0.3473987562209254 0.2542508445716206 -0.9025910548032103 1.396978774019742
  position 4.257414856590618 1.7199422245980838 1.2066275400060582
}
TexturedBackground {
}
TexturedBackgroundLight {
}
RectangleArena {
  translation 5.51275 4.45195 -9.12048e-14
  rotation 0 0 -1 0.9882900000000001
  floorSize 8 10
  floorAppearance Parquetry {
    type "light strip"
  }
  wallHeight 1.3
}
DEF bed Robot {
  translation 2.7973996589571075 3.6634397506210394 0.001401714736782543
  rotation -4.771532810442906e-08 2.451264772785977e-08 -0.9999999999999984 0.9291201607402898
  children [
    Pose {
      translation 0 0 -0.01
      children [
        DEF bars Solid {
          children [
            Solid {
              translation 0.3 0 0
              children [
                Shape {
                  appearance PBRAppearance {
                    baseColorMap ImageTexture {
                      url [
                        "C:/Users/HP/Downloads/124032577-aluminum-sheet-painted-white-texture-and-seamless-background.jpg"
                      ]
                    }
                    metalness 0
                  }
                  geometry Box {
                    size 0.1 0.22 0.01
                  }
                }
              ]
            }
          ]
          name "solid(8)"
        }
        DEF cush Solid {
          translation 0 0 0.05
          children [
            DEF cushion Shape {
              appearance PBRAppearance {
                baseColor 0.333333 0.333333 0
                baseColorMap ImageTexture {
                  url [
                    "../SKINS/360_F_338145328_POWWRCPh4LpTNB5lLnFVp4sutmoxZ1Eo.jpg"
                  ]
                }
                metalness 0
                IBLStrength 11
              }
              geometry Box {
                size 0.6 0.3 0.09
              }
            }
          ]
          name "solid(6)"
          boundingObject USE cushion
          physics Physics {
          }
        }
        DEF body Shape {
          appearance PBRAppearance {
            baseColorMap ImageTexture {
              url [
                "C:/Users/HP/Downloads/images (4).jpeg"
              ]
              filtering 1
            }
            metalness 0
          }
          geometry Box {
            size 0.65 0.33 0.01
          }
        }
        DEF bedhandles Solid {
          translation -0.36 0.14 -0.09
          children [
            Shape {
              appearance PBRAppearance {
                baseColorMap ImageTexture {
                  url [
                    "C:/Users/HP/Downloads/istockphoto-1052667096-612x612.jpg"
                  ]
                }
                metalness 0
                IBLStrength 4
              }
              geometry Mesh {
                url [
                  "../Blender components/bedhandles.stl"
                ]
              }
            }
          ]
          name "solid(11)"
        }
        DEF front Solid {
          translation -0.31 -0.16 -0.05
          rotation 0 0 1 1.5707996938995747
          children [
            DEF frontend Shape {
              appearance PBRAppearance {
                baseColorMap ImageTexture {
                  url [
                    "C:/Users/HP/Downloads/istockphoto-1052667096-612x612.jpg"
                  ]
                }
                metalness 0
                IBLStrength 4
              }
              geometry Mesh {
                url [
                  "../Blender components/bedendfinal.stl"
                ]
              }
            }
          ]
          name "solid(10)"
        }
        Solid {
          translation 0.34 -0.16 -0.06
          rotation 0 0 1 1.5707996938995747
          children [
            Shape {
              appearance PBRAppearance {
                baseColorMap ImageTexture {
                  url [
                    "C:/Users/HP/Downloads/istockphoto-1052667096-612x612.jpg"
                  ]
                }
                metalness 0
                IBLStrength 3
              }
              geometry Mesh {
                url [
                  "../Blender components/bedendfinal.stl"
                ]
              }
            }
          ]
          name "solid(9)"
        }
        Solid {
          translation -0.32 0.14 0.16
          children [
            Solid {
              translation 0 0 0.15
              children [
                Shape {
                  appearance PBRAppearance {
                    baseColorMap ImageTexture {
                      url [
                        "C:/Users/HP/Downloads/images (4).jpeg"
                      ]
                    }
                    metalness 0
                  }
                  geometry Box {
                    size 0.01 0.1 0.006
                  }
                }
              ]
            }
            Shape {
              appearance PBRAppearance {
                baseColorMap ImageTexture {
                  url [
                    "C:/Users/HP/Downloads/images (4).jpeg"
                  ]
                }
                metalness 0
              }
              geometry Cylinder {
                height 0.3
                radius 0.007
              }
            }
          ]
          name "solid(7)"
        }
      ]
    }
  ]
  name "robot(1)"
  boundingObject USE body
  physics Physics {
  }
  controller "slider"
}
Solid {
  children [
    Shape {
    }
  ]
}
DEF inf Solid {
  translation 6.89025 5.00239 -1.4
  rotation 0 0 -1 0.935933
  children [
    Shape {
      appearance PBRAppearance {
        baseColorMap ImageTexture {
          url [
            "C:/Users/HP/Downloads/istockphoto-1052667096-612x612.jpg"
          ]
        }
        metalness 0
        IBLStrength 6
      }
      geometry Mesh {
        url [
          "../Blender components/glucose6.stl"
        ]
      }
    }
  ]
  name "solid(4)"
}
DEF wardbed Solid {
  translation 6.56692 5.40251 -5.32907e-15
  rotation 0 0 1 0.562869
  children [
    Shape {
      appearance PBRAppearance {
        baseColorMap ImageTexture {
          url [
            "C:/Users/HP/Downloads/istockphoto-1052667096-612x612.jpg"
          ]
        }
        metalness 0
      }
      geometry Mesh {
        url [
          "../Blender components/ward3.stl"
        ]
      }
    }
  ]
  name "solid(3)"
}
Solid {
  translation 5.49322 7.14347 -1.31007e-14
  rotation 0 0 -1 0.981748
  children [
    Solid {
      translation -0.10577968125101167 3.5350650177790044e-05 0.0007295517202407702
      rotation -0.00710577848300809 0.9785996870635145 -0.20565057838805545 2.3614286985128676e-05
      children [
        DEF bedd Shape {
          appearance PBRAppearance {
            baseColorMap ImageTexture {
              url [
                "C:/Users/HP/Downloads/360_F_338145328_POWWRCPh4LpTNB5lLnFVp4sutmoxZ1Eo.jpg"
              ]
            }
            metalness 0
          }
          geometry Box {
            size 0.19 0.39 0.02
          }
        }
      ]
      name "solid(2)"
      boundingObject USE bedd
      physics Physics {
      }
    }
    Solid {
      translation -0.1058058571812448 3.227700722163718e-05 -0.0011642154204818183
      rotation -0.0030780691395472207 -0.9979659727885772 -0.06367450546742195 6.748428619776206e-05
      children [
        DEF bedd Shape {
          appearance PBRAppearance {
            baseColorMap ImageTexture {
              url [
                "C:/Users/HP/Downloads/360_F_338145328_POWWRCPh4LpTNB5lLnFVp4sutmoxZ1Eo.jpg"
              ]
            }
            metalness 0
          }
          geometry Box {
            size 0.19 0.39 0.02
          }
        }
      ]
      name "solid(3)"
      boundingObject USE bedd
      physics Physics {
      }
    }
    Solid {
      translation -0.19047896431195888 -8.476633122356247e-05 0.014430678636538121
      rotation 0.9999999999942626 2.4436455995415765e-06 -2.3459285525895896e-06 1.5707995023496824
      children [
        DEF handle Shape {
          appearance PBRAppearance {
            baseColorMap ImageTexture {
              url [
                "C:/Users/HP/Downloads/images (4).jpeg"
              ]
            }
            metalness 0
          }
          geometry Cylinder {
            height 0.5
            radius 0.01
          }
        }
        Solid {
          translation 0 0 0.23
          children [
            Shape {
              geometry Cylinder {
                height 0.04
                radius 0.013
              }
            }
          ]
          name "solid(1)"
        }
        Solid {
          translation 0 0 -0.23
          children [
            Shape {
              geometry Cylinder {
                height 0.04
                radius 0.013
              }
            }
          ]
        }
      ]
      name "solid(1)"
      boundingObject USE handle
      physics Physics {
      }
    }
    Solid {
      translation 0.012064510576097476 1.714026148036396e-05 0.013861125640847996
      rotation 0.999999992685106 -8.565581165049816e-05 8.539830194767522e-05 1.5708005540532644
      children [
        DEF handle Shape {
          appearance PBRAppearance {
            baseColorMap ImageTexture {
              url [
                "C:/Users/HP/Downloads/images (4).jpeg"
              ]
            }
            metalness 0
          }
          geometry Cylinder {
            height 0.5
            radius 0.01
          }
        }
        Solid {
          translation 0 0 0.23
          children [
            Shape {
              geometry Cylinder {
                height 0.04
                radius 0.013
              }
            }
          ]
          name "solid(1)"
        }
        Solid {
          translation 0 0 -0.23
          children [
            Shape {
              geometry Cylinder {
                height 0.04
                radius 0.013
              }
            }
          ]
        }
      ]
      boundingObject USE bedd
      physics Physics {
      }
    }
  ]
  name "solid(2)"
}
Solid {
  translation 2.81509 6.90183 -1.31007e-14
  rotation 0 0 -1 0.981748
  children [
    Solid {
      translation -0.105779681251013 3.535065017867822e-05 0.0007295517202403334
      rotation -0.007105778444496531 0.9785996870398579 -0.20565057850195756 2.3614286973129333e-05
      children [
        DEF bedd Shape {
          appearance PBRAppearance {
            baseColorMap ImageTexture {
              url [
                "C:/Users/HP/Downloads/360_F_338145328_POWWRCPh4LpTNB5lLnFVp4sutmoxZ1Eo.jpg"
              ]
            }
            metalness 0
          }
          geometry Box {
            size 0.19 0.39 0.02
          }
        }
      ]
      name "solid(2)"
      boundingObject USE bedd
      physics Physics {
      }
    }
    Solid {
      translation -0.10580585718124347 3.2277007223413534e-05 -0.0011642154204812105
      rotation -0.003078069138241055 -0.9979659727896641 -0.0636745054504512 6.748428620528668e-05
      children [
        DEF bedd Shape {
          appearance PBRAppearance {
            baseColorMap ImageTexture {
              url [
                "C:/Users/HP/Downloads/360_F_338145328_POWWRCPh4LpTNB5lLnFVp4sutmoxZ1Eo.jpg"
              ]
            }
            metalness 0
          }
          geometry Box {
            size 0.19 0.39 0.02
          }
        }
      ]
      name "solid(3)"
      boundingObject USE bedd
      physics Physics {
      }
    }
    Solid {
      translation -0.190478964311958 -8.476633122356247e-05 0.014430678636536819
      rotation 0.9999999999942626 2.4436454432392288e-06 -2.3459283944031294e-06 1.5707995023495938
      children [
        DEF handle Shape {
          appearance PBRAppearance {
            baseColorMap ImageTexture {
              url [
                "C:/Users/HP/Downloads/images (4).jpeg"
              ]
            }
            metalness 0
          }
          geometry Cylinder {
            height 0.5
            radius 0.01
          }
        }
        Solid {
          translation 0 0 0.23
          children [
            Shape {
              geometry Cylinder {
                height 0.04
                radius 0.013
              }
            }
          ]
          name "solid(1)"
        }
        Solid {
          translation 0 0 -0.23
          children [
            Shape {
              geometry Cylinder {
                height 0.04
                radius 0.013
              }
            }
          ]
        }
      ]
      name "solid(1)"
      boundingObject USE handle
      physics Physics {
      }
    }
    Solid {
      translation 0.012064510576097476 1.7140261473258533e-05 0.013861125640848827
      rotation 0.9999999926851059 -8.565581165183269e-05 8.539830194634061e-05 1.5708005540532652
      children [
        DEF handle Shape {
          appearance PBRAppearance {
            baseColorMap ImageTexture {
              url [
                "C:/Users/HP/Downloads/images (4).jpeg"
              ]
            }
            metalness 0
          }
          geometry Cylinder {
            height 0.5
            radius 0.01
          }
        }
        Solid {
          translation 0 0 0.23
          children [
            Shape {
              geometry Cylinder {
                height 0.04
                radius 0.013
              }
            }
          ]
          name "solid(1)"
        }
        Solid {
          translation 0 0 -0.23
          children [
            Shape {
              geometry Cylinder {
                height 0.04
                radius 0.013
              }
            }
          ]
        }
      ]
      boundingObject USE bedd
      physics Physics {
      }
    }
  ]
  name "solid(5)"
}
Cabinet {
  hidden translation_7 -1.2735599112445267e-06 -4.0752679009159465e-12 0
  hidden rotation_7 0 0 1 6.399801531773194e-06
  hidden translation_11 -9.203099043050394e-07 2.5036084316809593e-12 0
  hidden rotation_11 0 0 -1 5.440781060675363e-06
  hidden translation_15 0 0 0
  hidden translation_23 0 0 0
  hidden translation_31 0 0 0
  hidden translation_39 0 0 0
  translation 3.92565 8.26601 -6.21725e-15
  rotation 0 0 -1 1.01447
  rowsHeights [
    0.2, 0.2, 0.2, 0.1, 0.1
  ]
}
Cabinet {
  hidden translation_7 -1.2735599112425523e-06 -4.0752679009159465e-12 0
  hidden rotation_7 0 0 1 6.399801531773194e-06
  hidden translation_11 -9.203099043050394e-07 2.5036084316809593e-12 0
  hidden rotation_11 0 0 -1 5.440781060675363e-06
  hidden translation_15 0 0 0
  hidden translation_23 0 0 0
  hidden translation_31 0 0 0
  hidden translation_39 0 0 0
  translation 4.58436 8.68338 -6.21725e-15
  rotation 0 0 -1 1.01447
  name "cabinet(1)"
  rowsHeights [
    0.2, 0.2, 0.2, 0.1, 0.1
  ]
}
Cabinet {
  hidden translation_7 -1.2735599112405715e-06 -4.0752679009159465e-12 0
  hidden rotation_7 0 0 1 6.399801531773194e-06
  hidden translation_11 -9.203099043050394e-07 2.5036084316809593e-12 0
  hidden rotation_11 0 0 -1 5.440781060675363e-06
  hidden translation_15 0 0 0
  hidden translation_23 0 0 0
  hidden translation_31 0 0 0
  hidden translation_39 0 0 0
  translation 5.59857 9.31061 -6.21725e-15
  rotation 0 0 -1 1.01447
  name "cabinet(2)"
  rowsHeights [
    0.2, 0.2, 0.2, 0.1, 0.1
  ]
}
Wall {
  translation 4.45806 5.68255 -1.5099e-14
  rotation 0 0 1 0.608685
  size 0.1 5.1 0.8
}
Wall {
  translation 7.13776 4.42996 4.52971e-14
  rotation -5.20687e-09 -9.58979e-09 1 2.14675
  name "wall(3)"
  size 0.1 3 0.8
}
Wall {
  translation 6.36162 7.33074 2.66453e-15
  rotation 0 0 1 2.1402
  name "wall(2)"
  size 0.1 5 0.8
}
Solid {
  translation 4.58162 0.444896 0.07937
  rotation -2.8263398254629104e-05 -0.0003502979783677854 -0.9999999382462514 1.00787
  children [
    DEF bdy Shape {
      appearance PBRAppearance {
        baseColorMap ImageTexture {
          url [
            "../SKINS/360_F_338145328_POWWRCPh4LpTNB5lLnFVp4sutmoxZ1Eo.jpg"
          ]
        }
        metalness 0
        IBLStrength 4
      }
      geometry Box {
        size 0.2 0.5 0.05
      }
    }
  ]
  name "solid(1)"
  boundingObject USE bdy
  physics Physics {
    mass 1
  }
}
Robot {
  translation 4.754894974646318 0.22047241503143492 0.09359419497747663
  rotation -0.0004465059053399111 -0.0004739578995200369 0.9999997879981705 0.556585
  children [
    DistanceSensor {
      translation 0.33 0 -0.06
      rotation 0 1 0 1.5707996938995747
      children [
        DEF ds_f Shape {
          geometry Box {
            size 0.01 0.01 0.02
          }
        }
      ]
      name "ds_f"
      boundingObject USE ds_f
      physics Physics {
      }
      lookupTable [
        0 0 0
        0.2 1000 0
      ]
    }
    DistanceSensor {
      translation 0.33 0.14 -0.06
      rotation 0 1 0 1.5707996938995747
      children [
        DEF ds_l Shape {
          geometry Box {
            size 0.01 0.01 0.02
          }
        }
      ]
      name "ds_l"
      boundingObject USE ds_l
      physics Physics {
      }
      lookupTable [
        0 0 0
        0.2 1000 0
      ]
    }
    DistanceSensor {
      translation 0.33 -0.14 -0.06
      rotation 0 1 0 1.5707996938995747
      children [
        DEF ds_r Shape {
          geometry Box {
            size 0.01 0.01 0.02
          }
        }
      ]
      name "ds_r"
      boundingObject USE ds_r
      physics Physics {
      }
      lookupTable [
        0 0 0
        0.2 1000 0
      ]
    }
    SliderJoint {
      jointParameters JointParameters {
        position 0.17999954809684393
      }
      device [
        PositionSensor {
          name "psPickup"
        }
        LinearMotor {
          name "pickupMotor"
          acceleration 1
          maxForce 100
        }
      ]
      endPoint Solid {
        translation -8.396179618230803e-08 0.19999781211774748 -0.05000599028690608
        rotation -0.9983691156534206 0.05708740535103789 -0.00037021573881931185 4.609853866992945e-05
        children [
          DEF slider-bdy Shape {
            appearance PBRAppearance {
              baseColorMap ImageTexture {
                url [
                  "C:/Users/HP/Downloads/Metal floor plate dirty texture 4770x3178.jpg"
                ]
              }
              metalness 0
            }
            geometry Box {
              size 0.23 0.2 0.001
            }
          }
        ]
        name "solid(5)"
        boundingObject USE slider-bdy
        physics Physics {
        }
      }
    }
    HingeJoint {
      jointParameters HingeJointParameters {
        position 5959.013063741694
        axis 0 1 0
        anchor 0.19 -0.16 -0.04
      }
      device [
        RotationalMotor {
          name "motor1"
        }
      ]
      endPoint Solid {
        translation 0.19033434268187124 -0.15999676003728647 -0.040064167848833855
        rotation 0.20941668191141669 0.6914291884133787 -0.6914263017467798 2.7287052958945535
        children [
          DEF tyre Shape {
            geometry Cylinder {
              height 0.03
              radius 0.06
            }
          }
        ]
        boundingObject USE tyre
        physics Physics {
        }
      }
    }
    HingeJoint {
      jointParameters HingeJointParameters {
        position 5956.704653772605
        axis 0 1 0
        anchor -0.19 -0.16 -0.04
      }
      device [
        RotationalMotor {
          name "motor2"
        }
      ]
      endPoint Solid {
        translation -0.18965186381031512 -0.1599913000806117 -0.04003911736812784
        rotation 0.9851806242260941 0.1212918150065694 -0.12127420691101491 1.5857296246065296
        children [
          DEF tyre Shape {
            geometry Cylinder {
              height 0.03
              radius 0.06
            }
          }
        ]
        name "solid(2)"
        boundingObject USE tyre
        physics Physics {
        }
      }
    }
    HingeJoint {
      jointParameters HingeJointParameters {
        position 5956.305163156499
        axis 0 1 0
        anchor -0.19 0.16 -0.04
      }
      device [
        RotationalMotor {
          name "motor3"
        }
      ]
      endPoint Solid {
        translation -0.18965233291999598 0.16000856940650987 -0.040037937342253034
        rotation 0.9940613550664268 -0.07693911558545684 0.07695709750521433 1.5767598336649613
        children [
          DEF tyre Shape {
            geometry Cylinder {
              height 0.03
              radius 0.06
            }
          }
        ]
        name "solid(3)"
        boundingObject USE tyre
        physics Physics {
        }
      }
    }
    HingeJoint {
      jointParameters HingeJointParameters {
        position 5959.324888546862
        axis 0 1 0
        anchor 0.19 0.16 -0.04
      }
      device [
        RotationalMotor {
          name "motor4"
        }
      ]
      endPoint Solid {
        translation 0.190317317202022 0.16000324158163837 -0.040068675276534085
        rotation 0.09786235402755686 0.7037131250632859 -0.7037121551300994 2.9464662285749803
        children [
          DEF tyre Shape {
            geometry Cylinder {
              height 0.03
              radius 0.06
            }
          }
        ]
        name "solid(4)"
        boundingObject USE tyre
        physics Physics {
        }
      }
    }
    SliderJoint {
      jointParameters JointParameters {
        position 2.712105507421996e-09
        axis 0 1 0
        staticFriction 1
      }
      device [
        PositionSensor {
          name "ps"
          noise 1
        }
        LinearMotor {
          name "lm"
          acceleration 1
          maxPosition 0.25000000000533235
          maxForce 5
        }
      ]
      endPoint Solid {
        translation 0.13399999966283005 0.010000002264434066 0.0899994612413905
        rotation -0.7591217166357505 0.6509484275921005 0.0006032805014338426 1.9878232972837268e-06
        children [
          Solid {
            translation -0.149 -0.14 0
            rotation 0 0 1 1.5707996938995747
            children [
              DEF slider Shape {
                appearance PBRAppearance {
                }
                geometry Box {
                  size 0.026 0.29 0.002
                }
              }
            ]
            name "solid(2)"
          }
          Solid {
            translation -0.3 0 0
            children [
              DEF slider2 Shape {
                appearance PBRAppearance {
                  baseColorMap ImageTexture {
                    url [
                      "C:/Users/HP/Downloads/Metal floor plate dirty texture 4770x3178.jpg"
                    ]
                  }
                  metalness 0
                }
                geometry Box {
                  size 0.03 0.29 0.002
                }
              }
            ]
            boundingObject USE slider2
            physics Physics {
            }
          }
          DEF slider Shape {
            appearance PBRAppearance {
              baseColorMap ImageTexture {
                url [
                  "C:/Users/HP/Downloads/Metal floor plate dirty texture 4770x3178.jpg"
                ]
              }
              metalness 0
            }
            geometry Box {
              size 0.03 0.3 0.002
            }
          }
        ]
        name "solid(1)"
        boundingObject USE slider
        physics Physics {
        }
      }
    }
    Pose {
      translation 0 0 0.01
      children [
        DEF bars Solid {
          children [
            Solid {
              translation 0.3 0 0
              children [
                Shape {
                  appearance PBRAppearance {
                    baseColorMap ImageTexture {
                      url [
                        "C:/Users/HP/Downloads/124032577-aluminum-sheet-painted-white-texture-and-seamless-background.jpg"
                      ]
                    }
                    metalness 0
                  }
                  geometry Box {
                    size 0.1 0.22 0.01
                  }
                }
              ]
            }
          ]
          name "solid(8)"
        }
        Solid {
          translation 0 0 0.07
          children [
            Solid {
              translation -0.74 0.13 -0.2
              children [
                Shape {
                  appearance PBRAppearance {
                    baseColorMap ImageTexture {
                      url [
                        "C:/Users/HP/Downloads/360_F_338145328_POWWRCPh4LpTNB5lLnFVp4sutmoxZ1Eo.jpg"
                      ]
                    }
                    metalness 0
                  }
                  geometry Mesh {
                    url [
                      "../Blender components/minibed.stl"
                    ]
                  }
                }
              ]
            }
            DEF cushion Shape {
              appearance PBRAppearance {
                baseColorMap ImageTexture {
                  url [
                    "C:/Users/HP/Downloads/360_F_338145328_POWWRCPh4LpTNB5lLnFVp4sutmoxZ1Eo.jpg"
                  ]
                }
                metalness 0
              }
              geometry Box {
                size 0.6 0.3 0.01
              }
            }
          ]
          name "solid(6)"
          boundingObject USE cushion
          physics Physics {
          }
        }
        DEF body Shape {
          appearance PBRAppearance {
            baseColorMap ImageTexture {
              url [
                "C:/Users/HP/Downloads/images (4).jpeg"
              ]
              filtering 1
            }
            metalness 0
          }
          geometry Box {
            size 0.65 0.33 0.13
          }
        }
        DEF handesingle Solid {
          translation -0.36 0.16 -0.05
          children [
            Shape {
              appearance PBRAppearance {
                baseColorMap ImageTexture {
                  url [
                    "C:/Users/HP/Downloads/istockphoto-1052667096-612x612.jpg"
                  ]
                }
                metalness 0
                IBLStrength 3
              }
              geometry Mesh {
                url [
                  "../Blender components/bedhandlesinglw.stl"
                ]
              }
            }
          ]
          name "solid(12)"
        }
        DEF bedhandles Solid {
          translation -0.36 -0.18 -0.05
          children [
            Shape {
              appearance PBRAppearance {
                baseColorMap ImageTexture {
                  url [
                    "C:/Users/HP/Downloads/istockphoto-1052667096-612x612.jpg"
                  ]
                }
                metalness 0
                IBLStrength 4
              }
              geometry Mesh {
                url [
                  "../Blender components/bedhandles.stl"
                ]
              }
            }
          ]
          name "solid(11)"
        }
        Solid {
          translation -0.31 -0.16 -0.1
          rotation 0 0 1 1.5707996938995747
          children [
            DEF frontend Shape {
              appearance PBRAppearance {
                baseColorMap ImageTexture {
                  url [
                    "C:/Users/HP/Downloads/istockphoto-1052667096-612x612.jpg"
                  ]
                }
                metalness 0
                IBLStrength 4
              }
              geometry Mesh {
                url [
                  "../Blender components/bedendfinal.stl"
                ]
              }
            }
          ]
          name "solid(10)"
        }
        Solid {
          translation 0.34 -0.16 -0.11
          rotation 0 0 1 1.5707996938995747
          children [
            Shape {
              appearance PBRAppearance {
                baseColorMap ImageTexture {
                  url [
                    "C:/Users/HP/Downloads/istockphoto-1052667096-612x612.jpg"
                  ]
                }
                metalness 0
                IBLStrength 3
              }
              geometry Mesh {
                url [
                  "../Blender components/bedendfinal.stl"
                ]
              }
            }
          ]
          name "solid(9)"
        }
        Solid {
          translation -0.32 0.14 0.16
          children [
            Solid {
              translation 0 0 0.15
              children [
                Shape {
                  appearance PBRAppearance {
                    baseColorMap ImageTexture {
                      url [
                        "C:/Users/HP/Downloads/images (4).jpeg"
                      ]
                    }
                    metalness 0
                  }
                  geometry Box {
                    size 0.01 0.1 0.006
                  }
                }
              ]
            }
            Shape {
              appearance PBRAppearance {
                baseColorMap ImageTexture {
                  url [
                    "C:/Users/HP/Downloads/images (4).jpeg"
                  ]
                }
                metalness 0
              }
              geometry Cylinder {
                height 0.3
                radius 0.007
              }
            }
          ]
          name "solid(7)"
        }
      ]
    }
  ]
  name "robot(4)"
  boundingObject USE body
  physics Physics {
  }
  controller "slider"
}
Robot {
  translation 5.075542426616621 2.451966250792576 0.09952730344516027
  rotation 0.0007018557862753958 -0.00032291033023657456 -0.9999997015636425 3.1415300260852894
  children [
    HingeJoint {
      jointParameters HingeJointParameters {
        position 55107.34269758294
        anchor 0.055 0 -0.05
      }
      device [
        RotationalMotor {
          name "right_motor"
        }
      ]
      endPoint Solid {
        translation 0.055 0 -0.05
        rotation 0.6868632512909443 -0.2375583997981172 0.6868659845351137 3.6080610269403235
        children [
          DEF tyre Shape {
            geometry Cylinder {
              height 0.011
              radius 0.05
            }
          }
        ]
        name "solid(2)"
        boundingObject USE tyre
        physics Physics {
        }
      }
    }
    HingeJoint {
      jointParameters HingeJointParameters {
        position 55107.374825250954
        anchor -0.055 0 -0.05
      }
      device [
        RotationalMotor {
          name "left_motor"
        }
      ]
      endPoint Solid {
        translation -0.055 0 -0.05
        rotation 0.6847927045177689 -0.24922830040079413 0.6847950102903578 3.630095525081708
        children [
          DEF tyre Shape {
            geometry Cylinder {
              height 0.011
              radius 0.05
            }
          }
        ]
        name "solid(1)"
        boundingObject USE tyre
        physics Physics {
        }
      }
    }
    Pose {
      children [
        Solid {
          translation 0 0 0.1
          children [
            Shape {
              appearance PBRAppearance {
                baseColorMap ImageTexture {
                  url [
                    "C:/Users/HP/Downloads/images (4).jpeg"
                  ]
                }
                metalness 0
              }
              geometry Box {
                size 0.2 0.2 0.01
              }
            }
          ]
          name "solid(3)"
        }
        DEF body Shape {
          appearance PBRAppearance {
            baseColor 0.666667 0.666667 1
            metalness 0
          }
          geometry Box {
            size 0.1 0.1 0.2
          }
        }
      ]
    }
    HingeJoint {
      jointParameters HingeJointParameters {
        position 64.14945456036442
        anchor 0.08 0 0.05
      }
      device [
        RotationalMotor {
          name "motor"
        }
        PositionSensor {
          name "ps"
        }
      ]
      endPoint Solid {
        translation 0.08 9.899533612343414e-07 0.050004895965799254
        rotation 1 0 0 1.1867042220066688
        children [
          DEF axle Shape {
            appearance PBRAppearance {
              baseColor 0.431373 0.439216 1
              metalness 0
            }
            geometry Box {
              size 0.066 0.05 0.05
            }
          }
          Solid {
            translation 0.041 0 0.08
            children [
              DEF arm Shape {
                appearance PBRAppearance {
                  baseColor 0.419608 0.411765 0.498039
                  metalness 0
                }
                geometry Box {
                  size 0.015 0.016 0.21
                }
              }
            ]
            boundingObject USE arm
            physics Physics {
            }
          }
        ]
        boundingObject USE axle
        physics Physics {
        }
      }
    }
  ]
  boundingObject USE body
  physics Physics {
  }
  controller "arm"
}
DEF path Solid {
  translation 0.370198 -5.60077 1.27897e-13
  rotation 0 0 1 0.562869
  children [
    Solid {
      translation 104 -4 0
      children [
        Shape {
          geometry Mesh {
            url [
              "C:/Users/HP/Downloads/Bodacious Migelo-Snaget (18).stl"
            ]
          }
        }
      ]
    }
  ]
  name "solid(6)"
}
